
try {
    const getLength = (name) => {
        return name.length;
    }
    console.log(getLength());
} catch (err) {
    console.log('Something went wrong')
}
console.log('Hi there');

// try {
//     let a;
//     console.log(a.length);
//     console.log('hi there from inside');
// } catch (e) {
//     console.log('inside catch statement');
// }

// console.log('hi there');